<?xml version="1.0" encoding="utf-8"?>
<!-- =================================================================================== -->
<!-- |    This document was autogenerated by xacro from robot.xacro                    | -->
<!-- |    EDITING THIS FILE BY HAND IS NOT RECOMMENDED                                 | -->
<!-- =================================================================================== -->
<robot name="cyber_dog">
  <material name="orange">
    <color rgba="1.0 0.4235294117647059 0.0392156862745098 1.0"/>
  </material>
  <material name="white">
    <color rgba="1.0 1.0 1.0 1.0"/>
  </material>
  <material name="blue">
    <color rgba="0.0 0.0 0.8 1.0"/>
  </material>
  <link name="base">
    <visual>
      <origin rpy="0 0 0" xyz="0 0 0"/>
      <geometry>
        <box size="0.001 0.001 0.001"/>
      </geometry>
    </visual>
  </link>
  <joint name="floating_base" type="fixed">
    <origin rpy="0 0 0" xyz="0 0 0"/>
    <parent link="base"/>
    <child link="trunk"/>
  </joint>
  <link name="trunk">
    <visual>
      <origin rpy="0 0 0" xyz="0 0 0"/>
      <geometry>
        <mesh filename="../meshes/body.dae" scale="1 1 1"/>
      </geometry>
    </visual>
    <collision>
      <origin rpy="0 0 0" xyz="0 0 0"/>
      <geometry>
        <box size="0.236 0.19 0.109"/>
      </geometry>
    </collision>
    <inertial>
      <origin rpy="0 0 0" xyz="0.0273 -0.000242 0.0143"/>
      <mass value="4.03"/>
      <inertia ixx="0.0185" ixy="-0.000173" ixz="-0.0102" iyy="0.0517" iyz="-2.83e-05" izz="0.0483"/>
    </inertial>
  </link>
  <joint name="imu_joint" type="fixed">
    <parent link="trunk"/>
    <child link="imu_link"/>
    <origin rpy="0 0 0" xyz="33.4e-3 -17.2765e-3 51.0469e-3"/>
  </joint>
  <link name="imu_link">
    <inertial>
      <mass value="0.001"/>
      <origin rpy="0 0 0" xyz="0 0 0"/>
      <inertia ixx="0.0001" ixy="0" ixz="0" iyy="0.0001" iyz="0" izz="0.0001"/>
    </inertial>
    <visual>
      <origin rpy="0 0 0" xyz="0 0 0"/>
      <geometry>
        <box size="0.001 0.001 0.001"/>
      </geometry>
    </visual>
    <collision>
      <origin rpy="0 0 0" xyz="0 0 0"/>
      <geometry>
        <box size=".001 .001 .001"/>
      </geometry>
    </collision>
  </link>
  <!-- <joint name="scan_joint" type="fixed">
    <parent link="body"/>
    <child link="lidar_link"/>
    <origin rpy="0 0 0" xyz="0.21425 0 0.0908"/>
  </joint> -->
  <!-- <link name="lidar_link">
    <inertial>
      <mass value="0.001"/>
      <origin rpy="0 0 0" xyz="0 0 0"/>
      <inertia ixx="0.0001" ixy="0" ixz="0" iyy="0.0001" iyz="0" izz="0.0001"/>
    </inertial>
  </link> -->
  <!-- <joint name="D435_camera_joint" type="fixed">
    <parent link="body"/>
    <child link="D435_camera_link"/>
    <origin rpy="0 0 0" xyz="271.994e-3 25e-3 114.912e-3"/>
  </joint> -->
  <!-- <link name="D435_camera_link">
    <inertial>
      <mass value="0.001"/>
      <origin rpy="0 0 0" xyz="0 0 0"/>
      <inertia ixx="0.0001" ixy="0" ixz="0" iyy="0.0001" iyz="0" izz="0.0001"/>
    </inertial>
    <visual>
      <origin rpy="0 0 0" xyz="0 0 0"/>
      <geometry>
        <box size="0.001 0.001 0.001"/>
      </geometry>
    </visual>
    <collision>
      <origin rpy="0 0 0" xyz="0 0 0"/>
      <geometry>
        <box size=".001 .001 .001"/>
      </geometry>
    </collision>
  </link> -->
  <!-- <joint name="RGB_camera_joint" type="fixed">
    <parent link="body"/>
    <child link="RGB_camera_link"/>
    <origin rpy="0 0 0" xyz="275.76e-3 0 125.794e-3"/>
  </joint> -->
  <!-- <link name="RGB_camera_link">
    <inertial>
      <mass value="0.001"/>
      <origin rpy="0 0 0" xyz="0 0 0"/>
      <inertia ixx="0.0001" ixy="0" ixz="0" iyy="0.0001" iyz="0" izz="0.0001"/>
    </inertial>
    <visual>
      <origin rpy="0 0 0" xyz="0 0 0"/>
      <geometry>
        <box size="0.001 0.001 0.001"/>
      </geometry>
    </visual>
    <collision>
      <origin rpy="0 0 0" xyz="0 0 0"/>
      <geometry>
        <box size=".001 .001 .001"/>
      </geometry>
    </collision>
  </link> -->
  <!-- <joint name="AI_camera_joint" type="fixed">
    <parent link="body"/>
    <child link="AI_camera_link"/>
    <origin rpy="0 0 0" xyz="290.228e-3 0 147.420e-3"/>
  </joint> -->
  <!-- <link name="AI_camera_link">
    <inertial>
      <mass value="0.001"/>
      <origin rpy="0 0 0" xyz="0 0 0"/>
      <inertia ixx="0.0001" ixy="0" ixz="0" iyy="0.0001" iyz="0" izz="0.0001"/>
    </inertial>
    <visual>
      <origin rpy="0 0 0" xyz="0 0 0"/>
      <geometry>
        <box size="0.001 0.001 0.001"/>
      </geometry>
    </visual>
    <collision>
      <origin rpy="0 0 0" xyz="0 0 0"/>
      <geometry>
        <box size=".001 .001 .001"/>
      </geometry>
    </collision>
  </link> -->
  <joint name="FR_hip_joint" type="revolute">
    <origin rpy="0 0 0" xyz="0.164 -0.042 0"/>
    <parent link="trunk"/>
    <child link="FR_hip"/>
    <axis xyz="1 0 0"/>
    <dynamics damping="0.05" friction="0.2"/>
    <limit effort="12.0001" lower="-0.680678408278" upper="0.680678408278" velocity="38.1935483871"/>
  </joint>
  <link name="FR_hip">
    <visual>
      <origin rpy="3.14159265359 0 0" xyz="0 0 0"/>
      <geometry>
        <mesh filename="../meshes/abad.dae" scale="1 1 1"/>
      </geometry>
      <!-- <material name="orange"/> -->
    </visual>
    <!-- Remove similar to go1 -->
    <!-- <collision>
      <origin rpy="1.57079632679 0 0" xyz="0 0 0"/>
      <geometry>
        <cylinder length="0.035" radius="0.039"/>
      </geometry>
    </collision> -->
    <inertial>
      <origin rpy="0 0 0" xyz="-0.00392 -0.015 -0.000306"/>
      <mass value="0.354"/>
      <inertia ixx="0.00019" ixy="2.7e-05" ixz="-3.44e-07" iyy="0.000276" iyz="-1.95e-06" izz="0.000233"/>
    </inertial>
  </link>
  <joint name="FR_hip_rotor_inertia_joint" type="fixed">
    <origin rpy="0 0 0" xyz="-0.0642303 0 0"/>
    <parent link="FR_hip"/>
    <child link="FR_hip_rotor_inertia"/>
  </joint>
  <!-- this link is only for abad rotor inertial -->
  <link name="FR_hip_rotor_inertia">
    <inertial>
      <origin rpy="0 0 0" xyz="0 0 0"/>
      <mass value="0.0567"/>
      <inertia ixx="2.53e-05" ixy="0" ixz="0" iyy="2.53e-05" iyz="0" izz="4.78e-05"/>
    </inertial>
  </link>
  <joint name="FR_hip_rotor_joint" type="fixed">
    <origin rpy="0 0 0" xyz="0 -0.059 0"/>
    <parent link="FR_hip"/>
    <child link="FR_hip_rotor"/>
  </joint>
  <link name="FR_hip_rotor">
    <!-- Remove similar to go1 -->
    <!-- <collision>
      <origin rpy="1.57079632679 0 0" xyz="0 0 0"/>
      <geometry>
        <cylinder length="0.035" radius="0.039"/>
      </geometry>
    </collision> -->
  </link>
  <joint name="FR_thigh_joint" type="revolute">
    <origin rpy="0 0 3.14159265359" xyz="0 -0.094 0"/>
    <parent link="FR_hip"/>
    <child link="FR_thigh"/>
    <axis xyz="0 1 0"/>
    <dynamics damping="0.05" friction="0.2"/>
    <limit effort="12.0001" lower="-2.79252680319" upper="1.32645023152" velocity="38.1935483871"/>
  </joint>
  <link name="FR_thigh">
    <visual>
      <origin rpy="0 0 0" xyz="0 0 0"/>
      <geometry>
        <mesh filename="../meshes/hip_mirror.dae" scale="1 1 1"/>
      </geometry>
      <!-- <material name="orange"/> -->
    </visual>
    <collision>
      <origin rpy="0 1.57079632679 0" xyz="0 0 -0.06"/>
      <geometry>
        <box size="0.12 0.025 0.034"/>
      </geometry>
    </collision>
    <inertial>
      <origin rpy="0 0 0" xyz="0.00212 -0.0212 -0.0184"/>
      <mass value="0.482"/>
      <inertia ixx="0.00101" ixy="-2.23e-05" ixz="3.85e-05" iyy="0.000983" iyz="0.000199" izz="0.000347"/>
    </inertial>
  </link>
  <joint name="FR_thigh_rotor_fix" type="fixed">
    <origin rpy="0 0 0" xyz="0 -0.07577 0"/>
    <parent link="FR_thigh"/>
    <child link="FR_thigh_rotor"/>
  </joint>
  <!-- this link is only for hip rotor inertial -->
  <link name="FR_thigh_rotor">
    <inertial>
      <origin rpy="0 0 0" xyz="0 0 0"/>
      <mass value="0.0567"/>
      <inertia ixx="2.53e-05" ixy="0" ixz="0" iyy="2.53e-05" iyz="0" izz="4.78e-05"/>
    </inertial>
  </link>
  <joint name="FR_knee_rotor_fix" type="fixed">
    <origin rpy="0 0 0" xyz="0 -0.0342303 0"/>
    <parent link="FR_thigh"/>
    <child link="FR_knee_rotor"/>
  </joint>
  <!-- this link is only for knee rotor inertial -->
  <link name="FR_knee_rotor">
    <inertial>
      <origin rpy="0 0 0" xyz="0 0 0"/>
      <mass value="0.0567"/>
      <inertia ixx="2.53e-05" ixy="0" ixz="0" iyy="2.53e-05" iyz="0" izz="4.78e-05"/>
    </inertial>
  </link>
  <joint name="FR_calf_joint" type="revolute">
    <origin rpy="0 0 0" xyz="0 0 -0.12"/>
    <parent link="FR_thigh"/>
    <child link="FR_calf"/>
    <axis xyz="0 1 0"/>
    <dynamics damping="0.05" friction="0.2"/>
    <limit effort="12.0001" lower="0.523598775598" upper="2.53072741539" velocity="38.1935483871"/>
  </joint>
  <link name="FR_calf">
    <visual>
      <origin rpy="0 0 0" xyz="0 0 0"/>
      <geometry>
        <mesh filename="../meshes/knee.dae" scale="1 1 1"/>
      </geometry>
      <material name="white"/>
    </visual>
    <collision>
      <origin rpy="0 3.14159265359 0" xyz="0 0 -0.091705"/>
      <geometry>
        <box size="0.016 0.016 0.18341"/>
      </geometry>
    </collision>
    <collision name="FR_knee_rubber">
      <origin rpy="0 3.14159265359 0" xyz="0.01 0 -0.007"/>
      <geometry>
        <sphere radius="0.016"/>
      </geometry>
      <surface>
        <contact>
          <ode>
            <max_vel>0.00001</max_vel>
            <min_depth>0.0</min_depth>
          </ode>
        </contact>
      </surface>
    </collision>
    <inertial>
      <origin rpy="0 0 0" xyz="-0.0006 4.72e-05 -0.0893"/>
      <mass value="0.116"/>
      <inertia ixx="0.000668" ixy="3e-09" ixz="-2.37e-05" iyy="0.000674" iyz="-6.03e-07" izz="1.54e-05"/>
    </inertial>
  </link>
  <joint name="FR_foot_fixed" type="fixed" dont_collapse="true">
    <origin rpy="0 0 0" xyz="-0.0055 0 -0.17391"/>
    <parent link="FR_calf"/>
    <child link="FR_foot"/>
  </joint>
  <link name="FR_foot">
    <visual>
      <origin rpy="0 0 0" xyz="0 0 0"/>
      <geometry>
        <sphere radius="0.009"/>
      </geometry>
      <material name="white"/>
    </visual>
    <collision>
      <origin rpy="0 0 0" xyz="0 0 0"/>
      <geometry>
        <sphere radius="0.019"/>
      </geometry>
      <!-- <surface>
        <contact>
          <ode>
            <max_vel>0.001</max_vel>
            <min_depth>0.0</min_depth>
          </ode>
        </contact>
      </surface> -->
    </collision>
  </link>
  <joint name="FL_hip_joint" type="revolute">
    <origin rpy="0 0 0" xyz="0.164 0.042 0"/>
    <parent link="trunk"/>
    <child link="FL_hip"/>
    <axis xyz="1 0 0"/>
    <dynamics damping="0.05" friction="0.2"/>
    <limit effort="12.0001" lower="-0.680678408278" upper="0.680678408278" velocity="38.1935483871"/>
  </joint>
  <link name="FL_hip">
    <visual>
      <origin rpy="0 0 0" xyz="0 0 0"/>
      <geometry>
        <mesh filename="../meshes/abad.dae" scale="1 1 1"/>
      </geometry>
      <!-- <material name="orange"/> -->
    </visual>
    <!-- <collision>
      <origin rpy="1.57079632679 0 0" xyz="0 0 0"/>
      <geometry>
        <cylinder length="0.035" radius="0.039"/>
      </geometry>
    </collision> -->
    <inertial>
      <origin rpy="0 0 0" xyz="-0.00392 0.015 -0.000306"/>
      <mass value="0.354"/>
      <inertia ixx="0.00019" ixy="-2.7e-05" ixz="-3.44e-07" iyy="0.000276" iyz="1.95e-06" izz="0.000233"/>
    </inertial>
  </link>
  <joint name="FL_hip_rotor_inertia_joint" type="fixed">
    <origin rpy="0 0 0" xyz="-0.0642303 0 0"/>
    <parent link="FL_hip"/>
    <child link="FL_hip_rotor_inertia"/>
  </joint>
  <!-- this link is only for abad rotor inertial -->
  <link name="FL_hip_rotor_inertia">
    <inertial>
      <origin rpy="0 0 0" xyz="0 0 0"/>
      <mass value="0.0567"/>
      <inertia ixx="2.53e-05" ixy="0" ixz="0" iyy="2.53e-05" iyz="0" izz="4.78e-05"/>
    </inertial>
  </link>
  <joint name="FL_hip_rotor_joint" type="fixed">
    <origin rpy="0 0 0" xyz="0 0.059 0"/>
    <parent link="FL_hip"/>
    <child link="FL_hip_rotor"/>
  </joint>
  <link name="FL_hip_rotor">
    <!-- <collision>
      <origin rpy="1.57079632679 0 0" xyz="0 0 0"/>
      <geometry>
        <cylinder length="0.035" radius="0.039"/>
      </geometry>
    </collision> -->
  </link>
  <joint name="FL_thigh_joint" type="revolute">
    <origin rpy="0 0 3.14159265359" xyz="0 0.094 0"/>
    <parent link="FL_hip"/>
    <child link="FL_thigh"/>
    <axis xyz="0 1 0"/>
    <dynamics damping="0.05" friction="0.2"/>
    <limit effort="12.0001" lower="-2.79252680319" upper="1.32645023152" velocity="38.1935483871"/>
  </joint>
  <link name="FL_thigh">
    <visual>
      <origin rpy="0 0 0" xyz="0 0 0"/>
      <geometry>
        <mesh filename="../meshes/hip.dae" scale="1 1 1"/>
      </geometry>
      <!-- <material name="orange"/> -->
    </visual>
    <collision>
      <origin rpy="0 1.57079632679 0" xyz="0 0 -0.06"/>
      <geometry>
        <box size="0.12 0.025 0.034"/>
      </geometry>
    </collision>
    <inertial>
      <origin rpy="0 0 0" xyz="0.00212 0.0212 -0.0184"/>
      <mass value="0.482"/>
      <inertia ixx="0.00101" ixy="2.23e-05" ixz="3.85e-05" iyy="0.000983" iyz="-0.000199" izz="0.000347"/>
    </inertial>
  </link>
  <joint name="FL_thigh_rotor_fix" type="fixed">
    <origin rpy="0 0 0" xyz="0 0.07577 0"/>
    <parent link="FL_thigh"/>
    <child link="FL_thigh_rotor"/>
  </joint>
  <!-- this link is only for hip rotor inertial -->
  <link name="FL_thigh_rotor">
    <inertial>
      <origin rpy="0 0 0" xyz="0 0 0"/>
      <mass value="0.0567"/>
      <inertia ixx="2.53e-05" ixy="0" ixz="0" iyy="2.53e-05" iyz="0" izz="4.78e-05"/>
    </inertial>
  </link>
  <joint name="FL_knee_rotor_fix" type="fixed">
    <origin rpy="0 0 0" xyz="0 0.0342303 0"/>
    <parent link="FL_thigh"/>
    <child link="FL_knee_rotor"/>
  </joint>
  <!-- this link is only for knee rotor inertial -->
  <link name="FL_knee_rotor">
    <inertial>
      <origin rpy="0 0 0" xyz="0 0 0"/>
      <mass value="0.0567"/>
      <inertia ixx="2.53e-05" ixy="0" ixz="0" iyy="2.53e-05" iyz="0" izz="4.78e-05"/>
    </inertial>
  </link>
  <joint name="FL_calf_joint" type="revolute">
    <origin rpy="0 0 0" xyz="0 0 -0.12"/>
    <parent link="FL_thigh"/>
    <child link="FL_calf"/>
    <axis xyz="0 1 0"/>
    <dynamics damping="0.05" friction="0.2"/>
    <limit effort="12.0001" lower="0.523598775598" upper="2.53072741539" velocity="38.1935483871"/>
  </joint>
  <link name="FL_calf">
    <visual>
      <origin rpy="0 0 0" xyz="0 0 0"/>
      <geometry>
        <mesh filename="../meshes/knee.dae" scale="1 1 1"/>
      </geometry>
      <material name="white"/>
    </visual>
    <collision>
      <origin rpy="0 3.14159265359 0" xyz="0 0 -0.091705"/>
      <geometry>
        <box size="0.016 0.016 0.18341"/>
      </geometry>
    </collision>
    <collision name="FL_knee_rubber">
      <origin rpy="0 3.14159265359 0" xyz="0.01 0 -0.007"/>
      <geometry>
        <sphere radius="0.016"/>
      </geometry>
      <surface>
        <contact>
          <ode>
            <max_vel>0.00001</max_vel>
            <min_depth>0.0</min_depth>
          </ode>
        </contact>
      </surface>
    </collision>
    <inertial>
      <origin rpy="0 0 0" xyz="-0.0006 4.72e-05 -0.0893"/>
      <mass value="0.116"/>
      <inertia ixx="0.000668" ixy="3e-09" ixz="-2.37e-05" iyy="0.000674" iyz="-6.03e-07" izz="1.54e-05"/>
    </inertial>
  </link>
  <joint name="FL_foot_fixed" type="fixed" dont_collapse="true">
    <origin rpy="0 0 0" xyz="-0.0055 0 -0.17391"/>
    <parent link="FL_calf"/>
    <child link="FL_foot"/>
  </joint>
  <link name="FL_foot">
    <visual>
      <origin rpy="0 0 0" xyz="0 0 0"/>
      <geometry>
        <sphere radius="0.009"/>
      </geometry>
      <material name="white"/>
    </visual>
    <collision>
      <origin rpy="0 0 0" xyz="0 0 0"/>
      <geometry>
        <sphere radius="0.019"/>
      </geometry>
      <!-- <surface>
        <contact>
          <ode>
            <max_vel>0.001</max_vel>
            <min_depth>0.0</min_depth>
          </ode>
        </contact>
      </surface> -->
    </collision>
  </link>
  <joint name="RR_hip_joint" type="revolute">
    <origin rpy="0 0 0" xyz="-0.164 -0.042 0"/>
    <parent link="trunk"/>
    <child link="RR_hip"/>
    <axis xyz="1 0 0"/>
    <dynamics damping="0.05" friction="0.2"/>
    <limit effort="12.0001" lower="-0.680678408278" upper="0.680678408278" velocity="38.1935483871"/>
  </joint>
  <link name="RR_hip">
    <visual>
      <origin rpy="3.14159265359 3.14159265359 0" xyz="0 0 0"/>
      <geometry>
        <mesh filename="../meshes/abad.dae" scale="1 1 1"/>
      </geometry>
      <!-- <material name="orange"/> -->
    </visual>
    <!-- <collision>
      <origin rpy="1.57079632679 0 0" xyz="0 0 0"/>
      <geometry>
        <cylinder length="0.035" radius="0.039"/>
      </geometry>
    </collision> -->
    <inertial>
      <origin rpy="0 0 0" xyz="0.00392 -0.015 -0.000306"/>
      <mass value="0.354"/>
      <inertia ixx="0.00019" ixy="-2.7e-05" ixz="3.44e-07" iyy="0.000276" iyz="-1.95e-06" izz="0.000233"/>
    </inertial>
  </link>
  <joint name="RR_hip_rotor_inertia_joint" type="fixed">
    <origin rpy="0 0 0" xyz="0.0642303 0 0"/>
    <parent link="RR_hip"/>
    <child link="RR_hip_rotor_inertia"/>
  </joint>
  <!-- this link is only for abad rotor inertial -->
  <link name="RR_hip_rotor_inertia">
    <inertial>
      <origin rpy="0 0 0" xyz="0 0 0"/>
      <mass value="0.0567"/>
      <inertia ixx="2.53e-05" ixy="0" ixz="0" iyy="2.53e-05" iyz="0" izz="4.78e-05"/>
    </inertial>
  </link>
  <joint name="RR_hip_rotor_joint" type="fixed">
    <origin rpy="0 0 0" xyz="0 -0.059 0"/>
    <parent link="RR_hip"/>
    <child link="RR_hip_rotor"/>
  </joint>
  <link name="RR_hip_rotor">
    <!-- <collision>
      <origin rpy="1.57079632679 0 0" xyz="0 0 0"/>
      <geometry>
        <cylinder length="0.035" radius="0.039"/>
      </geometry>
    </collision> -->
  </link>
  <joint name="RR_thigh_joint" type="revolute">
    <origin rpy="0 0 3.14159265359" xyz="0 -0.094 0"/>
    <parent link="RR_hip"/>
    <child link="RR_thigh"/>
    <axis xyz="0 1 0"/>
    <dynamics damping="0.05" friction="0.2"/>
    <limit effort="12.0001" lower="-3.14159265359" upper="0.977384381117" velocity="38.1935483871"/>
  </joint>
  <link name="RR_thigh">
    <visual>
      <origin rpy="0 0 0" xyz="0 0 0"/>
      <geometry>
        <mesh filename="../meshes/hip_mirror.dae" scale="1 1 1"/>
      </geometry>
      <!-- <material name="orange"/> -->
    </visual>
    <collision>
      <origin rpy="0 1.57079632679 0" xyz="0 0 -0.06"/>
      <geometry>
        <box size="0.12 0.025 0.034"/>
      </geometry>
    </collision>
    <inertial>
      <origin rpy="0 0 0" xyz="0.00212 -0.0212 -0.0184"/>
      <mass value="0.482"/>
      <inertia ixx="0.00101" ixy="-2.23e-05" ixz="3.85e-05" iyy="0.000983" iyz="0.000199" izz="0.000347"/>
    </inertial>
  </link>
  <joint name="RR_thigh_rotor_fix" type="fixed">
    <origin rpy="0 0 0" xyz="0 -0.07577 0"/>
    <parent link="RR_thigh"/>
    <child link="RR_thigh_rotor"/>
  </joint>
  <!-- this link is only for hip rotor inertial -->
  <link name="RR_thigh_rotor">
    <inertial>
      <origin rpy="0 0 0" xyz="0 0 0"/>
      <mass value="0.0567"/>
      <inertia ixx="2.53e-05" ixy="0" ixz="0" iyy="2.53e-05" iyz="0" izz="4.78e-05"/>
    </inertial>
  </link>
  <joint name="RR_knee_rotor_fix" type="fixed">
    <origin rpy="0 0 0" xyz="0 -0.0342303 0"/>
    <parent link="RR_thigh"/>
    <child link="RR_knee_rotor"/>
  </joint>
  <!-- this link is only for knee rotor inertial -->
  <link name="RR_knee_rotor">
    <inertial>
      <origin rpy="0 0 0" xyz="0 0 0"/>
      <mass value="0.0567"/>
      <inertia ixx="2.53e-05" ixy="0" ixz="0" iyy="2.53e-05" iyz="0" izz="4.78e-05"/>
    </inertial>
  </link>
  <joint name="RR_calf_joint" type="revolute">
    <origin rpy="0 0 0" xyz="0 0 -0.12"/>
    <parent link="RR_thigh"/>
    <child link="RR_calf"/>
    <axis xyz="0 1 0"/>
    <dynamics damping="0.05" friction="0.2"/>
    <limit effort="12.0001" lower="0.523598775598" upper="2.53072741539" velocity="38.1935483871"/>
  </joint>
  <link name="RR_calf">
    <visual>
      <origin rpy="0 0 0" xyz="0 0 0"/>
      <geometry>
        <mesh filename="../meshes/knee.dae" scale="1 1 1"/>
      </geometry>
      <material name="white"/>
    </visual>
    <collision>
      <origin rpy="0 3.14159265359 0" xyz="0 0 -0.091705"/>
      <geometry>
        <box size="0.016 0.016 0.18341"/>
      </geometry>
    </collision>
    <collision name="RR_knee_rubber">
      <origin rpy="0 3.14159265359 0" xyz="0.01 0 -0.007"/>
      <geometry>
        <sphere radius="0.016"/>
      </geometry>
      <surface>
        <contact>
          <ode>
            <max_vel>0.00001</max_vel>
            <min_depth>0.0</min_depth>
          </ode>
        </contact>
      </surface>
    </collision>
    <inertial>
      <origin rpy="0 0 0" xyz="-0.0006 4.72e-05 -0.0893"/>
      <mass value="0.116"/>
      <inertia ixx="0.000668" ixy="3e-09" ixz="-2.37e-05" iyy="0.000674" iyz="-6.03e-07" izz="1.54e-05"/>
    </inertial>
  </link>
  <joint name="RR_foot_fixed" type="fixed" dont_collapse="true">
    <origin rpy="0 0 0" xyz="-0.0055 0 -0.17391"/>
    <parent link="RR_calf"/>
    <child link="RR_foot"/>
  </joint>
  <link name="RR_foot">
    <visual>
      <origin rpy="0 0 0" xyz="0 0 0"/>
      <geometry>
        <sphere radius="0.009"/>
      </geometry>
      <material name="white"/>
    </visual>
    <collision>
      <origin rpy="0 0 0" xyz="0 0 0"/>
      <geometry>
        <sphere radius="0.019"/>
      </geometry>
      <!-- <surface>
        <contact>
          <ode>
            <max_vel>0.001</max_vel>
            <min_depth>0.0</min_depth>
          </ode>
        </contact>
      </surface> -->
    </collision>
  </link>
  <joint name="RL_hip_joint" type="revolute">
    <origin rpy="0 0 0" xyz="-0.164 0.042 0"/>
    <parent link="trunk"/>
    <child link="RL_hip"/>
    <axis xyz="1 0 0"/>
    <dynamics damping="0.05" friction="0.2"/>
    <limit effort="12.0001" lower="-0.680678408278" upper="0.680678408278" velocity="38.1935483871"/>
  </joint>
  <link name="RL_hip">
    <visual>
      <origin rpy="0 3.14159265359 0" xyz="0 0 0"/>
      <geometry>
        <mesh filename="../meshes/abad.dae" scale="1 1 1"/>
      </geometry>
      <!-- <material name="orange"/> -->
    </visual>
    <!-- <collision>
      <origin rpy="1.57079632679 0 0" xyz="0 0 0"/>
      <geometry>
        <cylinder length="0.035" radius="0.039"/>
      </geometry>
    </collision> -->
    <inertial>
      <origin rpy="0 0 0" xyz="0.00392 0.015 -0.000306"/>
      <mass value="0.354"/>
      <inertia ixx="0.00019" ixy="2.7e-05" ixz="3.44e-07" iyy="0.000276" iyz="1.95e-06" izz="0.000233"/>
    </inertial>
  </link>
  <joint name="RL_hip_rotor_inertia_joint" type="fixed">
    <origin rpy="0 0 0" xyz="0.0642303 0 0"/>
    <parent link="RL_hip"/>
    <child link="RL_hip_rotor_inertia"/>
  </joint>
  <!-- this link is only for abad rotor inertial -->
  <link name="RL_hip_rotor_inertia">
    <inertial>
      <origin rpy="0 0 0" xyz="0 0 0"/>
      <mass value="0.0567"/>
      <inertia ixx="2.53e-05" ixy="0" ixz="0" iyy="2.53e-05" iyz="0" izz="4.78e-05"/>
    </inertial>
  </link>
  <joint name="RL_hip_rotor_joint" type="fixed">
    <origin rpy="0 0 0" xyz="0 0.059 0"/>
    <parent link="RL_hip"/>
    <child link="RL_hip_rotor"/>
  </joint>
  <link name="RL_hip_rotor">
    <!-- <collision>
      <origin rpy="1.57079632679 0 0" xyz="0 0 0"/>
      <geometry>
        <cylinder length="0.035" radius="0.039"/>
      </geometry>
    </collision> -->
  </link>
  <joint name="RL_thigh_joint" type="revolute">
    <origin rpy="0 0 3.14159265359" xyz="0 0.094 0"/>
    <parent link="RL_hip"/>
    <child link="RL_thigh"/>
    <axis xyz="0 1 0"/>
    <dynamics damping="0.05" friction="0.2"/>
    <limit effort="12.0001" lower="-3.14159265359" upper="0.977384381117" velocity="38.1935483871"/>
  </joint>
  <link name="RL_thigh">
    <visual>
      <origin rpy="0 0 0" xyz="0 0 0"/>
      <geometry>
        <mesh filename="../meshes/hip.dae" scale="1 1 1"/>
      </geometry>
      <!-- <material name="orange"/> -->
    </visual>
    <collision>
      <origin rpy="0 1.57079632679 0" xyz="0 0 -0.06"/>
      <geometry>
        <box size="0.12 0.025 0.034"/>
      </geometry>
    </collision>
    <inertial>
      <origin rpy="0 0 0" xyz="0.00212 0.0212 -0.0184"/>
      <mass value="0.482"/>
      <inertia ixx="0.00101" ixy="2.23e-05" ixz="3.85e-05" iyy="0.000983" iyz="-0.000199" izz="0.000347"/>
    </inertial>
  </link>
  <joint name="RL_thigh_rotor_fix" type="fixed">
    <origin rpy="0 0 0" xyz="0 0.07577 0"/>
    <parent link="RL_thigh"/>
    <child link="RL_thigh_rotor"/>
  </joint>
  <!-- this link is only for hip rotor inertial -->
  <link name="RL_thigh_rotor">
    <inertial>
      <origin rpy="0 0 0" xyz="0 0 0"/>
      <mass value="0.0567"/>
      <inertia ixx="2.53e-05" ixy="0" ixz="0" iyy="2.53e-05" iyz="0" izz="4.78e-05"/>
    </inertial>
  </link>
  <joint name="RL_knee_rotor_fix" type="fixed">
    <origin rpy="0 0 0" xyz="0 0.0342303 0"/>
    <parent link="RL_thigh"/>
    <child link="RL_knee_rotor"/>
  </joint>
  <!-- this link is only for knee rotor inertial -->
  <link name="RL_knee_rotor">
    <inertial>
      <origin rpy="0 0 0" xyz="0 0 0"/>
      <mass value="0.0567"/>
      <inertia ixx="2.53e-05" ixy="0" ixz="0" iyy="2.53e-05" iyz="0" izz="4.78e-05"/>
    </inertial>
  </link>
  <joint name="RL_calf_joint" type="revolute">
    <origin rpy="0 0 0" xyz="0 0 -0.12"/>
    <parent link="RL_thigh"/>
    <child link="RL_calf"/>
    <axis xyz="0 1 0"/>
    <dynamics damping="0.05" friction="0.2"/>
    <limit effort="12.0001" lower="0.523598775598" upper="2.53072741539" velocity="38.1935483871"/>
  </joint>
  <link name="RL_calf">
    <visual>
      <origin rpy="0 0 0" xyz="0 0 0"/>
      <geometry>
        <mesh filename="../meshes/knee.dae" scale="1 1 1"/>
      </geometry>
      <material name="white"/>
    </visual>
    <collision>
      <origin rpy="0 3.14159265359 0" xyz="0 0 -0.091705"/>
      <geometry>
        <box size="0.016 0.016 0.18341"/>
      </geometry>
    </collision>
    <collision name="RL_knee_rubber">
      <origin rpy="0 3.14159265359 0" xyz="0.01 0 -0.007"/>
      <geometry>
        <sphere radius="0.016"/>
      </geometry>
      <surface>
        <contact>
          <ode>
            <max_vel>0.00001</max_vel>
            <min_depth>0.0</min_depth>
          </ode>
        </contact>
      </surface>
    </collision>
    <inertial>
      <origin rpy="0 0 0" xyz="-0.0006 4.72e-05 -0.0893"/>
      <mass value="0.116"/>
      <inertia ixx="0.000668" ixy="3e-09" ixz="-2.37e-05" iyy="0.000674" iyz="-6.03e-07" izz="1.54e-05"/>
    </inertial>
  </link>
  <joint name="RL_foot_fixed" type="fixed" dont_collapse="true">
    <origin rpy="0 0 0" xyz="-0.0055 0 -0.17391"/>
    <parent link="RL_calf"/>
    <child link="RL_foot"/>
  </joint>
  <link name="RL_foot">
    <visual>
      <origin rpy="0 0 0" xyz="0 0 0"/>
      <geometry>
        <sphere radius="0.009"/>
      </geometry>
      <material name="white"/>
    </visual>
    <collision>
      <origin rpy="0 0 0" xyz="0 0 0"/>
      <geometry>
        <sphere radius="0.019"/>
      </geometry>
      <!-- <surface>
        <contact>
          <ode>
            <max_vel>0.001</max_vel>
            <min_depth>0.0</min_depth>
          </ode>
        </contact>
      </surface> -->
    </collision>
  </link>
  <!-- This link is only for head collision -->
  <joint name="head_joint" type="fixed">
    <parent link="trunk"/>
    <child link="head"/>
    <origin rpy="0 0 0" xyz="0 0 0"/>
  </joint>
  <link name="head">
    <collision>
      <origin rpy="0 0 0" xyz="0.256 0 0.120"/>
      <geometry>
        <box size="0.076 0.060 0.040"/>
      </geometry>
    </collision>
    <collision>
      <origin rpy="0 0 0" xyz="0.225 0 0.150"/>
      <geometry>
        <box size="0.020 0.080 0.100"/>
      </geometry>
    </collision>
  </link>
</robot>

